<?xml version="1.0"?>
<robot xmlns:xacro="http://www.ros.org/wiki/xacro">
  <xacro:include filename="$(find flex_gazebo)/urdf/truss/3d/peduncle.gazebo.xacro" />

  <xacro:macro name="peduncle" params="peduncle_length peduncle_radius parent_link">
    <xacro:property name = "PI" value="3.14159"/>

    <joint name="truss_joint" type="floating">
      <xacro:insert_block name="origin" />
      <parent link="world"/>
      <child link="peduncle" />
    </joint>

    <link name="peduncle">
      <collision>
        <!-- origin is in the center of the cylinder-->
        <origin xyz="0 0 0" rpy="${PI/2} 0 0"/>
        <geometry>
          <cylinder radius="${peduncle_radius}" length="${peduncle_length}"/>
        </geometry>
      </collision>

      <visual>
        <origin xyz="0 0 0" rpy="${PI/2} 0 0"/>
        <geometry>
          <cylinder radius="${peduncle_radius}" length="${peduncle_length}"/>
        </geometry>
        <material name="Green"/>
      </visual>

      <inertial>
        <origin xyz="0 0 0" rpy="0 0 0"/>
        <mass value="10"/>
        <inertia
           ixx="1.0" ixy="0.0" ixz="0.0"
           iyy="1.0" iyz="0.0"
           izz="1.0"/>
       </inertial>
     </link>

     <xacro:peduncle_gazebo/>
 </xacro:macro>
</robot>
