<?xml version="1.0"?>
<robot xmlns:xacro="http://www.ros.org/wiki/xacro">
  <xacro:include filename="$(find flex_gazebo)/urdf/truss/3d/peduncle.gazebo.xacro" />

  <xacro:macro name="peduncle" params="peduncle_length peduncle_radius parent_link">
    <xacro:property name = "rho" value="1000"/> <!-- [kg/m^3]-->
    <xacro:property name = "volume" value="${pi*peduncle_length*peduncle_radius**2}"/> <!-- [m^3]-->
    <xacro:property name = "mass" value="${rho * volume}"/> <!-- [kg]-->

    <joint name="truss_joint" type="floating">
      <xacro:insert_block name="origin" />
      <parent link="world"/>
      <child link="peduncle" />
    </joint>

    <link name="peduncle">
      <collision>
        <!-- origin is in the center of the cylinder-->
        <origin xyz="0 0 0" rpy="${pi/2} 0 0"/>
        <geometry>
          <cylinder radius="${peduncle_radius}" length="${peduncle_length}"/>
        </geometry>
      </collision>

      <visual>
        <origin xyz="0 0 0" rpy="${pi/2} 0 0"/>
        <geometry>
          <cylinder radius="${peduncle_radius}" length="${peduncle_length}"/>
        </geometry>
        <material name="Green"/>
      </visual>

      <inertial>
        <origin xyz="0 0 0" rpy="0 0 0"/>
        <mass value="${mass}"/>
        <inertia
           ixx="${1/12*mass*peduncle_length**2}" ixy="0.0" ixz="0.0"
           iyy="${1/12*mass*peduncle_length**2}" iyz="0.0"
           izz="${1/2*mass*peduncle_radius**2}"/>
       </inertial>
     </link>

     <xacro:peduncle_gazebo/>
 </xacro:macro>
</robot>
