<?xml version="1.0"?>
<robot name="custom_gripper" xmlns:xacro="http://ros.org/wiki/xacro">

  <joint name="left_finger" type="prismatic">
    <axis xyz="0 1 0"/>
    <limit effort="10" lower="0.015" upper="0.037" velocity="1"/>
    <origin rpy="0 0 0" xyz="0 0 0"/>
    <parent link="$(arg robot_name)/fingers_link"/>
    <child link="$(arg robot_name)/left_finger_link"/>
  </joint>

  <transmission name="trans_left_finger">
    <type>transmission_interface/SimpleTransmission</type>
    <joint name="left_finger">
      <hardwareInterface>hardware_interface/EffortJointInterface</hardwareInterface>
    </joint>
    <actuator name="left_finger_motor">
      <mechanicalReduction>1</mechanicalReduction>
    </actuator>
  </transmission>

  <link name="$(arg robot_name)/left_finger_link">
    <visual>
      <origin rpy="${pi} ${pi} 0" xyz="0 0.005 0"/>
      <geometry>
        <mesh filename="package://flex_gazebo_interbotix/meshes/finger.STL" scale="0.001 0.001 0.001"/>
      </geometry>
      <material name="interbotix_black"/>
    </visual>
    <collision>
      <origin rpy="${pi} ${pi} 0" xyz="0 0.005 0"/>
      <geometry>
        <mesh filename="package://flex_gazebo_interbotix/meshes/finger.STL" scale="0.001 0.001 0.001"/>
      </geometry>
    </collision>
    <inertial>
      <origin rpy="${pi} ${pi} ${pi/2}" xyz="0.0138160000 0.0000000000 0.0000000000"/>
       <mass value="0.016246" />
      <inertia ixx="0.0000047310" iyy="0.0000015506" izz="0.0000037467" ixy="-0.0000004560" ixz="0.0000000000" iyz="0.0000000000" />
    </inertial>
  </link>

  <joint name="right_finger" type="prismatic">
    <axis xyz="0 1 0"/>
    <limit effort="10" lower="-0.037" upper="-0.015" velocity="1"/>
    <origin rpy="0 0 0" xyz="0 0 0"/>
    <parent link="$(arg robot_name)/fingers_link"/>
    <child link="$(arg robot_name)/right_finger_link"/>
    <xacro:unless value="$(arg load_gazebo_configs)">
      <mimic joint="left_finger" multiplier="-1" offset="0"/>
    </xacro:unless>
  </joint>

  <transmission name="trans_right_finger">
    <type>transmission_interface/SimpleTransmission</type>
    <joint name="right_finger">
      <hardwareInterface>hardware_interface/EffortJointInterface</hardwareInterface>
    </joint>
    <actuator name="right_finger_motor">
      <mechanicalReduction>1</mechanicalReduction>
    </actuator>
  </transmission>

  <link name="$(arg robot_name)/right_finger_link">
    <visual>
      <origin rpy="0 ${pi} 0" xyz="0 -0.005 0"/>
      <geometry>
        <mesh filename="package://flex_gazebo_interbotix/meshes/finger.STL" scale="0.001 0.001 0.001"/>
      </geometry>
      <material name="interbotix_black"/>
    </visual>
    <collision>
      <origin rpy="0 ${pi} 0" xyz="0 -0.005 0"/>
      <geometry>
        <mesh filename="package://flex_gazebo_interbotix/meshes/finger.STL" scale="0.001 0.001 0.001"/>
      </geometry>
    </collision>
    <inertial>
      <origin rpy="0 ${pi} ${pi/2}" xyz="0.0138160000 0.0000000000  0.0000000000"/>
      <mass value="0.016246" />
      <inertia ixx="0.0000047310" iyy="0.0000015506" izz="0.0000037467" ixy="0.0000004560" ixz="0.0000000000" iyz="0.0000000000" />
    </inertial>
  </link>

  <joint name="ee_gripper" type="fixed">
    <axis xyz="1 0 0"/>
    <origin rpy="0 0 0" xyz="0.027575 0 0"/>
    <parent link="$(arg robot_name)/fingers_link"/>
    <child link="$(arg robot_name)/ee_gripper_link"/>
  </joint>

  <link name="$(arg robot_name)/ee_gripper_link">
    <inertial>
      <mass value="0.001" />
      <inertia ixx="0.0001" iyy="0.0001" izz="0.0001" ixy="0" ixz="0" iyz="0" />
    </inertial>
  </link>

</robot>
